INFO:[12/07/2021 21:44:03] Scheduler started
INFO:[12/07/2021 21:44:14] Scheduler started
ERROR:[12/07/2021 21:44:18] Error while getting Updates: Conflict: terminated by other getUpdates request; make sure that only one bot instance is running
ERROR:[12/07/2021 21:44:18] No error handlers are registered, logging exception.
Traceback (most recent call last):
  File "C:\Python39\lib\site-packages\python_telegram_bot-13.4.1-py3.9.egg\telegram\ext\updater.py", line 516, in _network_loop_retry
    if not action_cb():
  File "C:\Python39\lib\site-packages\python_telegram_bot-13.4.1-py3.9.egg\telegram\ext\updater.py", line 467, in polling_action_cb
    updates = self.bot.get_updates(
  File "C:\Python39\lib\site-packages\python_telegram_bot-13.4.1-py3.9.egg\telegram\bot.py", line 127, in decorator
    result = func(*args, **kwargs)
  File "C:\Python39\lib\site-packages\python_telegram_bot-13.4.1-py3.9.egg\telegram\bot.py", line 2761, in get_updates
    result = self._post(
  File "C:\Python39\lib\site-packages\python_telegram_bot-13.4.1-py3.9.egg\telegram\bot.py", line 259, in _post
    return self.request.post(
  File "C:\Python39\lib\site-packages\python_telegram_bot-13.4.1-py3.9.egg\telegram\utils\request.py", line 349, in post
    result = self._request_wrapper(
  File "C:\Python39\lib\site-packages\python_telegram_bot-13.4.1-py3.9.egg\telegram\utils\request.py", line 276, in _request_wrapper
    raise Conflict(message)
telegram.error.Conflict: Conflict: terminated by other getUpdates request; make sure that only one bot instance is running
ERROR:[12/07/2021 21:44:22] No error handlers are registered, logging exception.
Traceback (most recent call last):
  File "C:\Python39\lib\site-packages\python_telegram_bot-13.4.1-py3.9.egg\telegram\ext\dispatcher.py", line 442, in process_update
    handler.handle_update(update, self, check, context)
  File "C:\Python39\lib\site-packages\python_telegram_bot-13.4.1-py3.9.egg\telegram\ext\conversationhandler.py", line 549, in handle_update
    new_state = handler.handle_update(update, dispatcher, check_result, context)
  File "C:\Python39\lib\site-packages\python_telegram_bot-13.4.1-py3.9.egg\telegram\ext\handler.py", line 160, in handle_update
    return self.callback(update, context)
  File "c:\Users\juanp\OneDrive\Escritorio\Repositorio\ChatWars\WaTavBot.py", line 1422, in buy
    Newcompra(player=str(user.id),items=weapon)
TypeError: Newcompra() got an unexpected keyword argument 'player'
ERROR:[12/07/2021 21:44:23] Error while getting Updates: Conflict: terminated by other getUpdates request; make sure that only one bot instance is running
ERROR:[12/07/2021 21:44:23] No error handlers are registered, logging exception.
Traceback (most recent call last):
  File "C:\Python39\lib\site-packages\python_telegram_bot-13.4.1-py3.9.egg\telegram\ext\updater.py", line 516, in _network_loop_retry
    if not action_cb():
  File "C:\Python39\lib\site-packages\python_telegram_bot-13.4.1-py3.9.egg\telegram\ext\updater.py", line 467, in polling_action_cb
    updates = self.bot.get_updates(
  File "C:\Python39\lib\site-packages\python_telegram_bot-13.4.1-py3.9.egg\telegram\bot.py", line 127, in decorator
    result = func(*args, **kwargs)
  File "C:\Python39\lib\site-packages\python_telegram_bot-13.4.1-py3.9.egg\telegram\bot.py", line 2761, in get_updates
    result = self._post(
  File "C:\Python39\lib\site-packages\python_telegram_bot-13.4.1-py3.9.egg\telegram\bot.py", line 259, in _post
    return self.request.post(
  File "C:\Python39\lib\site-packages\python_telegram_bot-13.4.1-py3.9.egg\telegram\utils\request.py", line 349, in post
    result = self._request_wrapper(
  File "C:\Python39\lib\site-packages\python_telegram_bot-13.4.1-py3.9.egg\telegram\utils\request.py", line 276, in _request_wrapper
    raise Conflict(message)
telegram.error.Conflict: Conflict: terminated by other getUpdates request; make sure that only one bot instance is running
ERROR:[12/07/2021 21:44:27] Error while getting Updates: Conflict: terminated by other getUpdates request; make sure that only one bot instance is running
ERROR:[12/07/2021 21:44:27] No error handlers are registered, logging exception.
Traceback (most recent call last):
  File "C:\Python39\lib\site-packages\python_telegram_bot-13.4.1-py3.9.egg\telegram\ext\updater.py", line 516, in _network_loop_retry
    if not action_cb():
  File "C:\Python39\lib\site-packages\python_telegram_bot-13.4.1-py3.9.egg\telegram\ext\updater.py", line 467, in polling_action_cb
    updates = self.bot.get_updates(
  File "C:\Python39\lib\site-packages\python_telegram_bot-13.4.1-py3.9.egg\telegram\bot.py", line 127, in decorator
    result = func(*args, **kwargs)
  File "C:\Python39\lib\site-packages\python_telegram_bot-13.4.1-py3.9.egg\telegram\bot.py", line 2761, in get_updates
    result = self._post(
  File "C:\Python39\lib\site-packages\python_telegram_bot-13.4.1-py3.9.egg\telegram\bot.py", line 259, in _post
    return self.request.post(
  File "C:\Python39\lib\site-packages\python_telegram_bot-13.4.1-py3.9.egg\telegram\utils\request.py", line 349, in post
    result = self._request_wrapper(
  File "C:\Python39\lib\site-packages\python_telegram_bot-13.4.1-py3.9.egg\telegram\utils\request.py", line 276, in _request_wrapper
    raise Conflict(message)
telegram.error.Conflict: Conflict: terminated by other getUpdates request; make sure that only one bot instance is running
WARNING:[12/07/2021 21:44:32] Actualizar: 
‚îÇ
‚îúupdate_id: 994730966
‚îîmessage:
‚†Ä‚îúmessage_id: 4562
‚†Ä‚îúdate: 1626140670
‚†Ä‚îúchat:
‚îÇ‚îÇ‚îúid: 622952731
‚îÇ‚îÇ‚îútype: private
‚îÇ‚îÇ‚îúusername: JuanShotLC
‚îÇ‚îÇ‚îúfirst_name: üëë JuanShotLC üëë
‚îÇ‚îÇ‚îîlast_name: ‚öíÔ∏è ¬≤‚Å∑
‚†Ä‚îútext: /buy_01
‚†Ä‚îúentities:
‚îÇ‚îÇ‚îî0:
‚îÇ‚îÇ‚†Ä‚îútype: bot_command
‚îÇ‚îÇ‚†Ä‚îúoffset: 0
‚îÇ‚îÇ‚†Ä‚îîlength: 7
‚†Ä‚îúcaption_entities:
‚†Ä‚îúphoto:
‚†Ä‚îúnew_chat_members:
‚†Ä‚îúnew_chat_photo:
‚†Ä‚îúdelete_chat_photo: False
‚†Ä‚îúgroup_chat_created: False
‚†Ä‚îúsupergroup_chat_created: False
‚†Ä‚îúchannel_chat_created: False
‚†Ä‚îîfrom:
‚îÇ‚†Ä‚îúid: 622952731
‚îÇ‚†Ä‚îúfirst_name: üëë JuanShotLC üëë
‚îÇ‚†Ä‚îúis_bot: False
‚îÇ‚†Ä‚îúlast_name: ‚öíÔ∏è ¬≤‚Å∑
‚îÇ‚†Ä‚îúusername: JuanShotLC
‚îÇ‚†Ä‚îîlanguage_code: es 
...Error causado : 

&lt;class &#x27;UnboundLocalError&#x27;&gt;:local variable &#x27;text&#x27; referenced before assignment en WaTavBot.py en la linea 1428

Notas: local variable &#x27;text&#x27; referenced before assignment
ERROR:[12/07/2021 21:44:32] Error while getting Updates: Conflict: terminated by other getUpdates request; make sure that only one bot instance is running
ERROR:[12/07/2021 21:44:32] No error handlers are registered, logging exception.
Traceback (most recent call last):
  File "C:\Python39\lib\site-packages\python_telegram_bot-13.4.1-py3.9.egg\telegram\ext\updater.py", line 516, in _network_loop_retry
    if not action_cb():
  File "C:\Python39\lib\site-packages\python_telegram_bot-13.4.1-py3.9.egg\telegram\ext\updater.py", line 467, in polling_action_cb
    updates = self.bot.get_updates(
  File "C:\Python39\lib\site-packages\python_telegram_bot-13.4.1-py3.9.egg\telegram\bot.py", line 127, in decorator
    result = func(*args, **kwargs)
  File "C:\Python39\lib\site-packages\python_telegram_bot-13.4.1-py3.9.egg\telegram\bot.py", line 2761, in get_updates
    result = self._post(
  File "C:\Python39\lib\site-packages\python_telegram_bot-13.4.1-py3.9.egg\telegram\bot.py", line 259, in _post
    return self.request.post(
  File "C:\Python39\lib\site-packages\python_telegram_bot-13.4.1-py3.9.egg\telegram\utils\request.py", line 349, in post
    result = self._request_wrapper(
  File "C:\Python39\lib\site-packages\python_telegram_bot-13.4.1-py3.9.egg\telegram\utils\request.py", line 276, in _request_wrapper
    raise Conflict(message)
telegram.error.Conflict: Conflict: terminated by other getUpdates request; make sure that only one bot instance is running
ERROR:[12/07/2021 21:44:36] Error while getting Updates: Conflict: terminated by other getUpdates request; make sure that only one bot instance is running
ERROR:[12/07/2021 21:44:36] No error handlers are registered, logging exception.
Traceback (most recent call last):
  File "C:\Python39\lib\site-packages\python_telegram_bot-13.4.1-py3.9.egg\telegram\ext\updater.py", line 516, in _network_loop_retry
    if not action_cb():
  File "C:\Python39\lib\site-packages\python_telegram_bot-13.4.1-py3.9.egg\telegram\ext\updater.py", line 467, in polling_action_cb
    updates = self.bot.get_updates(
  File "C:\Python39\lib\site-packages\python_telegram_bot-13.4.1-py3.9.egg\telegram\bot.py", line 127, in decorator
    result = func(*args, **kwargs)
  File "C:\Python39\lib\site-packages\python_telegram_bot-13.4.1-py3.9.egg\telegram\bot.py", line 2761, in get_updates
    result = self._post(
  File "C:\Python39\lib\site-packages\python_telegram_bot-13.4.1-py3.9.egg\telegram\bot.py", line 259, in _post
    return self.request.post(
  File "C:\Python39\lib\site-packages\python_telegram_bot-13.4.1-py3.9.egg\telegram\utils\request.py", line 349, in post
    result = self._request_wrapper(
  File "C:\Python39\lib\site-packages\python_telegram_bot-13.4.1-py3.9.egg\telegram\utils\request.py", line 276, in _request_wrapper
    raise Conflict(message)
telegram.error.Conflict: Conflict: terminated by other getUpdates request; make sure that only one bot instance is running
ERROR:[12/07/2021 21:44:41] Error while getting Updates: Conflict: terminated by other getUpdates request; make sure that only one bot instance is running
ERROR:[12/07/2021 21:44:41] No error handlers are registered, logging exception.
Traceback (most recent call last):
  File "C:\Python39\lib\site-packages\python_telegram_bot-13.4.1-py3.9.egg\telegram\ext\updater.py", line 516, in _network_loop_retry
    if not action_cb():
  File "C:\Python39\lib\site-packages\python_telegram_bot-13.4.1-py3.9.egg\telegram\ext\updater.py", line 467, in polling_action_cb
    updates = self.bot.get_updates(
  File "C:\Python39\lib\site-packages\python_telegram_bot-13.4.1-py3.9.egg\telegram\bot.py", line 127, in decorator
    result = func(*args, **kwargs)
  File "C:\Python39\lib\site-packages\python_telegram_bot-13.4.1-py3.9.egg\telegram\bot.py", line 2761, in get_updates
    result = self._post(
  File "C:\Python39\lib\site-packages\python_telegram_bot-13.4.1-py3.9.egg\telegram\bot.py", line 259, in _post
    return self.request.post(
  File "C:\Python39\lib\site-packages\python_telegram_bot-13.4.1-py3.9.egg\telegram\utils\request.py", line 349, in post
    result = self._request_wrapper(
  File "C:\Python39\lib\site-packages\python_telegram_bot-13.4.1-py3.9.egg\telegram\utils\request.py", line 276, in _request_wrapper
    raise Conflict(message)
telegram.error.Conflict: Conflict: terminated by other getUpdates request; make sure that only one bot instance is running
ERROR:[12/07/2021 21:44:47] Error while getting Updates: Conflict: terminated by other getUpdates request; make sure that only one bot instance is running
ERROR:[12/07/2021 21:44:47] No error handlers are registered, logging exception.
Traceback (most recent call last):
  File "C:\Python39\lib\site-packages\python_telegram_bot-13.4.1-py3.9.egg\telegram\ext\updater.py", line 516, in _network_loop_retry
    if not action_cb():
  File "C:\Python39\lib\site-packages\python_telegram_bot-13.4.1-py3.9.egg\telegram\ext\updater.py", line 467, in polling_action_cb
    updates = self.bot.get_updates(
  File "C:\Python39\lib\site-packages\python_telegram_bot-13.4.1-py3.9.egg\telegram\bot.py", line 127, in decorator
    result = func(*args, **kwargs)
  File "C:\Python39\lib\site-packages\python_telegram_bot-13.4.1-py3.9.egg\telegram\bot.py", line 2761, in get_updates
    result = self._post(
  File "C:\Python39\lib\site-packages\python_telegram_bot-13.4.1-py3.9.egg\telegram\bot.py", line 259, in _post
    return self.request.post(
  File "C:\Python39\lib\site-packages\python_telegram_bot-13.4.1-py3.9.egg\telegram\utils\request.py", line 349, in post
    result = self._request_wrapper(
  File "C:\Python39\lib\site-packages\python_telegram_bot-13.4.1-py3.9.egg\telegram\utils\request.py", line 276, in _request_wrapper
    raise Conflict(message)
telegram.error.Conflict: Conflict: terminated by other getUpdates request; make sure that only one bot instance is running
ERROR:[12/07/2021 21:44:55] Error while getting Updates: Conflict: terminated by other getUpdates request; make sure that only one bot instance is running
ERROR:[12/07/2021 21:44:55] No error handlers are registered, logging exception.
Traceback (most recent call last):
  File "C:\Python39\lib\site-packages\python_telegram_bot-13.4.1-py3.9.egg\telegram\ext\updater.py", line 516, in _network_loop_retry
    if not action_cb():
  File "C:\Python39\lib\site-packages\python_telegram_bot-13.4.1-py3.9.egg\telegram\ext\updater.py", line 467, in polling_action_cb
    updates = self.bot.get_updates(
  File "C:\Python39\lib\site-packages\python_telegram_bot-13.4.1-py3.9.egg\telegram\bot.py", line 127, in decorator
    result = func(*args, **kwargs)
  File "C:\Python39\lib\site-packages\python_telegram_bot-13.4.1-py3.9.egg\telegram\bot.py", line 2761, in get_updates
    result = self._post(
  File "C:\Python39\lib\site-packages\python_telegram_bot-13.4.1-py3.9.egg\telegram\bot.py", line 259, in _post
    return self.request.post(
  File "C:\Python39\lib\site-packages\python_telegram_bot-13.4.1-py3.9.egg\telegram\utils\request.py", line 349, in post
    result = self._request_wrapper(
  File "C:\Python39\lib\site-packages\python_telegram_bot-13.4.1-py3.9.egg\telegram\utils\request.py", line 276, in _request_wrapper
    raise Conflict(message)
telegram.error.Conflict: Conflict: terminated by other getUpdates request; make sure that only one bot instance is running
ERROR:[12/07/2021 21:45:04] Error while getting Updates: Conflict: terminated by other getUpdates request; make sure that only one bot instance is running
ERROR:[12/07/2021 21:45:04] No error handlers are registered, logging exception.
Traceback (most recent call last):
  File "C:\Python39\lib\site-packages\python_telegram_bot-13.4.1-py3.9.egg\telegram\ext\updater.py", line 516, in _network_loop_retry
    if not action_cb():
  File "C:\Python39\lib\site-packages\python_telegram_bot-13.4.1-py3.9.egg\telegram\ext\updater.py", line 467, in polling_action_cb
    updates = self.bot.get_updates(
  File "C:\Python39\lib\site-packages\python_telegram_bot-13.4.1-py3.9.egg\telegram\bot.py", line 127, in decorator
    result = func(*args, **kwargs)
  File "C:\Python39\lib\site-packages\python_telegram_bot-13.4.1-py3.9.egg\telegram\bot.py", line 2761, in get_updates
    result = self._post(
  File "C:\Python39\lib\site-packages\python_telegram_bot-13.4.1-py3.9.egg\telegram\bot.py", line 259, in _post
    return self.request.post(
  File "C:\Python39\lib\site-packages\python_telegram_bot-13.4.1-py3.9.egg\telegram\utils\request.py", line 349, in post
    result = self._request_wrapper(
  File "C:\Python39\lib\site-packages\python_telegram_bot-13.4.1-py3.9.egg\telegram\utils\request.py", line 276, in _request_wrapper
    raise Conflict(message)
telegram.error.Conflict: Conflict: terminated by other getUpdates request; make sure that only one bot instance is running
INFO:[12/07/2021 21:45:15] Received signal 2 (SIGINT), stopping...
INFO:[12/07/2021 21:45:15] Scheduler has been shut down
ERROR:[12/07/2021 21:45:15] Error while getting Updates: Conflict: terminated by other getUpdates request; make sure that only one bot instance is running
ERROR:[12/07/2021 21:45:15] No error handlers are registered, logging exception.
Traceback (most recent call last):
  File "C:\Python39\lib\site-packages\python_telegram_bot-13.4.1-py3.9.egg\telegram\ext\updater.py", line 516, in _network_loop_retry
    if not action_cb():
  File "C:\Python39\lib\site-packages\python_telegram_bot-13.4.1-py3.9.egg\telegram\ext\updater.py", line 467, in polling_action_cb
    updates = self.bot.get_updates(
  File "C:\Python39\lib\site-packages\python_telegram_bot-13.4.1-py3.9.egg\telegram\bot.py", line 127, in decorator
    result = func(*args, **kwargs)
  File "C:\Python39\lib\site-packages\python_telegram_bot-13.4.1-py3.9.egg\telegram\bot.py", line 2761, in get_updates
    result = self._post(
  File "C:\Python39\lib\site-packages\python_telegram_bot-13.4.1-py3.9.egg\telegram\bot.py", line 259, in _post
    return self.request.post(
  File "C:\Python39\lib\site-packages\python_telegram_bot-13.4.1-py3.9.egg\telegram\utils\request.py", line 349, in post
    result = self._request_wrapper(
  File "C:\Python39\lib\site-packages\python_telegram_bot-13.4.1-py3.9.egg\telegram\utils\request.py", line 276, in _request_wrapper
    raise Conflict(message)
telegram.error.Conflict: Conflict: terminated by other getUpdates request; make sure that only one bot instance is running
WARNING:[12/07/2021 21:45:15] Exiting immediately!
INFO:[12/07/2021 21:49:30] Scheduler started
ERROR:[12/07/2021 21:49:55] No error handlers are registered, logging exception.
Traceback (most recent call last):
  File "C:\Python39\lib\site-packages\python_telegram_bot-13.4.1-py3.9.egg\telegram\ext\dispatcher.py", line 442, in process_update
    handler.handle_update(update, self, check, context)
  File "C:\Python39\lib\site-packages\python_telegram_bot-13.4.1-py3.9.egg\telegram\ext\conversationhandler.py", line 549, in handle_update
    new_state = handler.handle_update(update, dispatcher, check_result, context)
  File "C:\Python39\lib\site-packages\python_telegram_bot-13.4.1-py3.9.egg\telegram\ext\handler.py", line 160, in handle_update
    return self.callback(update, context)
  File "c:\Users\juanp\OneDrive\Escritorio\Repositorio\ChatWars\WaTavBot.py", line 1422, in buy
    Newcompra(player=str(user.id),items=weapon)
TypeError: Newcompra() got an unexpected keyword argument 'player'
ERROR:[12/07/2021 21:51:39] No error handlers are registered, logging exception.
Traceback (most recent call last):
  File "C:\Python39\lib\site-packages\python_telegram_bot-13.4.1-py3.9.egg\telegram\ext\dispatcher.py", line 442, in process_update
    handler.handle_update(update, self, check, context)
  File "C:\Python39\lib\site-packages\python_telegram_bot-13.4.1-py3.9.egg\telegram\ext\conversationhandler.py", line 549, in handle_update
    new_state = handler.handle_update(update, dispatcher, check_result, context)
  File "C:\Python39\lib\site-packages\python_telegram_bot-13.4.1-py3.9.egg\telegram\ext\handler.py", line 160, in handle_update
    return self.callback(update, context)
  File "c:\Users\juanp\OneDrive\Escritorio\Repositorio\ChatWars\WaTavBot.py", line 1422, in buy
    Newcompra(player=str(user.id),items=weapon)
TypeError: Newcompra() got an unexpected keyword argument 'player'
ERROR:[12/07/2021 21:53:08] No error handlers are registered, logging exception.
Traceback (most recent call last):
  File "C:\Python39\lib\site-packages\python_telegram_bot-13.4.1-py3.9.egg\telegram\ext\dispatcher.py", line 442, in process_update
    handler.handle_update(update, self, check, context)
  File "C:\Python39\lib\site-packages\python_telegram_bot-13.4.1-py3.9.egg\telegram\ext\conversationhandler.py", line 549, in handle_update
    new_state = handler.handle_update(update, dispatcher, check_result, context)
  File "C:\Python39\lib\site-packages\python_telegram_bot-13.4.1-py3.9.egg\telegram\ext\handler.py", line 160, in handle_update
    return self.callback(update, context)
  File "c:\Users\juanp\OneDrive\Escritorio\Repositorio\ChatWars\WaTavBot.py", line 1422, in buy
    Newcompra(player=str(user.id),items=weapon)
TypeError: Newcompra() got an unexpected keyword argument 'player'
INFO:[12/07/2021 21:55:47] Scheduler started
ERROR:[12/07/2021 21:56:59] No error handlers are registered, logging exception.
Traceback (most recent call last):
  File "C:\Python39\lib\site-packages\python_telegram_bot-13.4.1-py3.9.egg\telegram\ext\dispatcher.py", line 442, in process_update
    handler.handle_update(update, self, check, context)
  File "C:\Python39\lib\site-packages\python_telegram_bot-13.4.1-py3.9.egg\telegram\ext\conversationhandler.py", line 549, in handle_update
    new_state = handler.handle_update(update, dispatcher, check_result, context)
  File "C:\Python39\lib\site-packages\python_telegram_bot-13.4.1-py3.9.egg\telegram\ext\handler.py", line 160, in handle_update
    return self.callback(update, context)
  File "c:\Users\juanp\OneDrive\Escritorio\Repositorio\ChatWars\WaTavBot.py", line 1416, in buy
    if(weapon not in player["bolso_arm"]):
KeyError: 'bolso_arm'
ERROR:[12/07/2021 21:57:59] No error handlers are registered, logging exception.
Traceback (most recent call last):
  File "C:\Python39\lib\site-packages\python_telegram_bot-13.4.1-py3.9.egg\telegram\ext\dispatcher.py", line 442, in process_update
    handler.handle_update(update, self, check, context)
  File "C:\Python39\lib\site-packages\python_telegram_bot-13.4.1-py3.9.egg\telegram\ext\conversationhandler.py", line 549, in handle_update
    new_state = handler.handle_update(update, dispatcher, check_result, context)
  File "C:\Python39\lib\site-packages\python_telegram_bot-13.4.1-py3.9.egg\telegram\ext\handler.py", line 160, in handle_update
    return self.callback(update, context)
  File "c:\Users\juanp\OneDrive\Escritorio\Repositorio\ChatWars\WaTavBot.py", line 1422, in buy
    Newcompra(layer=str(user.id),items=weapon)
TypeError: Newcompra() got an unexpected keyword argument 'layer'
ERROR:[12/07/2021 21:58:09] No error handlers are registered, logging exception.
Traceback (most recent call last):
  File "C:\Python39\lib\site-packages\python_telegram_bot-13.4.1-py3.9.egg\telegram\ext\dispatcher.py", line 442, in process_update
    handler.handle_update(update, self, check, context)
  File "C:\Python39\lib\site-packages\python_telegram_bot-13.4.1-py3.9.egg\telegram\ext\conversationhandler.py", line 549, in handle_update
    new_state = handler.handle_update(update, dispatcher, check_result, context)
  File "C:\Python39\lib\site-packages\python_telegram_bot-13.4.1-py3.9.egg\telegram\ext\handler.py", line 160, in handle_update
    return self.callback(update, context)
  File "c:\Users\juanp\OneDrive\Escritorio\Repositorio\ChatWars\WaTavBot.py", line 1422, in buy
    Newcompra(layer=str(user.id),items=weapon)
TypeError: Newcompra() got an unexpected keyword argument 'layer'
INFO:[12/07/2021 21:59:11] Received signal 2 (SIGINT), stopping...
INFO:[12/07/2021 21:59:11] Scheduler has been shut down
WARNING:[12/07/2021 21:59:12] Exiting immediately!
INFO:[12/07/2021 21:59:19] Scheduler started
ERROR:[12/07/2021 21:59:35] No error handlers are registered, logging exception.
Traceback (most recent call last):
  File "C:\Python39\lib\site-packages\python_telegram_bot-13.4.1-py3.9.egg\telegram\ext\dispatcher.py", line 442, in process_update
    handler.handle_update(update, self, check, context)
  File "C:\Python39\lib\site-packages\python_telegram_bot-13.4.1-py3.9.egg\telegram\ext\conversationhandler.py", line 549, in handle_update
    new_state = handler.handle_update(update, dispatcher, check_result, context)
  File "C:\Python39\lib\site-packages\python_telegram_bot-13.4.1-py3.9.egg\telegram\ext\handler.py", line 160, in handle_update
    return self.callback(update, context)
  File "c:\Users\juanp\OneDrive\Escritorio\Repositorio\ChatWars\WaTavBot.py", line 1422, in buy
    Newcompra(layer=int(user.id),items=weapon)
TypeError: Newcompra() got an unexpected keyword argument 'layer'
ERROR:[12/07/2021 22:00:25] No error handlers are registered, logging exception.
Traceback (most recent call last):
  File "C:\Python39\lib\site-packages\python_telegram_bot-13.4.1-py3.9.egg\telegram\ext\dispatcher.py", line 442, in process_update
    handler.handle_update(update, self, check, context)
  File "C:\Python39\lib\site-packages\python_telegram_bot-13.4.1-py3.9.egg\telegram\ext\conversationhandler.py", line 549, in handle_update
    new_state = handler.handle_update(update, dispatcher, check_result, context)
  File "C:\Python39\lib\site-packages\python_telegram_bot-13.4.1-py3.9.egg\telegram\ext\handler.py", line 160, in handle_update
    return self.callback(update, context)
  File "c:\Users\juanp\OneDrive\Escritorio\Repositorio\ChatWars\WaTavBot.py", line 1422, in buy
    Newcompra(layer=622952731,items=weapon)
TypeError: Newcompra() got an unexpected keyword argument 'layer'
ERROR:[12/07/2021 22:01:17] No error handlers are registered, logging exception.
Traceback (most recent call last):
  File "C:\Python39\lib\site-packages\python_telegram_bot-13.4.1-py3.9.egg\telegram\ext\dispatcher.py", line 442, in process_update
    handler.handle_update(update, self, check, context)
  File "C:\Python39\lib\site-packages\python_telegram_bot-13.4.1-py3.9.egg\telegram\ext\conversationhandler.py", line 549, in handle_update
    new_state = handler.handle_update(update, dispatcher, check_result, context)
  File "C:\Python39\lib\site-packages\python_telegram_bot-13.4.1-py3.9.egg\telegram\ext\handler.py", line 160, in handle_update
    return self.callback(update, context)
  File "c:\Users\juanp\OneDrive\Escritorio\Repositorio\ChatWars\WaTavBot.py", line 1422, in buy
    Newcompra(layer=622952731,items=weapon)
TypeError: Newcompra() got an unexpected keyword argument 'layer'
ERROR:[12/07/2021 22:01:39] No error handlers are registered, logging exception.
Traceback (most recent call last):
  File "C:\Python39\lib\site-packages\python_telegram_bot-13.4.1-py3.9.egg\telegram\ext\dispatcher.py", line 442, in process_update
    handler.handle_update(update, self, check, context)
  File "C:\Python39\lib\site-packages\python_telegram_bot-13.4.1-py3.9.egg\telegram\ext\conversationhandler.py", line 549, in handle_update
    new_state = handler.handle_update(update, dispatcher, check_result, context)
  File "C:\Python39\lib\site-packages\python_telegram_bot-13.4.1-py3.9.egg\telegram\ext\handler.py", line 160, in handle_update
    return self.callback(update, context)
  File "c:\Users\juanp\OneDrive\Escritorio\Repositorio\ChatWars\WaTavBot.py", line 1422, in buy
    Newcompra(layer=622952731,items=weapon)
TypeError: Newcompra() got an unexpected keyword argument 'layer'
INFO:[12/07/2021 22:01:52] Scheduler started
ERROR:[12/07/2021 22:02:03] No error handlers are registered, logging exception.
Traceback (most recent call last):
  File "C:\Python39\lib\site-packages\python_telegram_bot-13.4.1-py3.9.egg\telegram\ext\dispatcher.py", line 442, in process_update
    handler.handle_update(update, self, check, context)
  File "C:\Python39\lib\site-packages\python_telegram_bot-13.4.1-py3.9.egg\telegram\ext\conversationhandler.py", line 549, in handle_update
    new_state = handler.handle_update(update, dispatcher, check_result, context)
  File "C:\Python39\lib\site-packages\python_telegram_bot-13.4.1-py3.9.egg\telegram\ext\handler.py", line 160, in handle_update
    return self.callback(update, context)
  File "c:\Users\juanp\OneDrive\Escritorio\Repositorio\ChatWars\WaTavBot.py", line 1422, in buy
    Newcompra(layer=622952731,items=weapon)
TypeError: Newcompra() got an unexpected keyword argument 'layer'
INFO:[12/07/2021 22:02:31] Received signal 2 (SIGINT), stopping...
INFO:[12/07/2021 22:02:31] Scheduler has been shut down
WARNING:[12/07/2021 22:02:31] Exiting immediately!
INFO:[12/07/2021 22:02:35] Scheduler started
ERROR:[12/07/2021 22:02:39] No error handlers are registered, logging exception.
Traceback (most recent call last):
  File "C:\Python39\lib\site-packages\python_telegram_bot-13.4.1-py3.9.egg\telegram\ext\dispatcher.py", line 442, in process_update
    handler.handle_update(update, self, check, context)
  File "C:\Python39\lib\site-packages\python_telegram_bot-13.4.1-py3.9.egg\telegram\ext\conversationhandler.py", line 549, in handle_update
    new_state = handler.handle_update(update, dispatcher, check_result, context)
  File "C:\Python39\lib\site-packages\python_telegram_bot-13.4.1-py3.9.egg\telegram\ext\handler.py", line 160, in handle_update
    return self.callback(update, context)
  File "c:\Users\juanp\OneDrive\Escritorio\Repositorio\ChatWars\WaTavBot.py", line 1422, in buy
    Newcompra(622952731,weapon)
  File "c:\Users\juanp\OneDrive\Escritorio\Repositorio\ChatWars\WaTavBot.py", line 1454, in Newcompra
    "ataque": TiendaDB[items]["ataque"],
KeyError: 'ataque'
INFO:[12/07/2021 22:02:47] Received signal 2 (SIGINT), stopping...
INFO:[12/07/2021 22:02:47] Scheduler has been shut down
WARNING:[12/07/2021 22:02:47] Exiting immediately!
INFO:[12/07/2021 22:03:00] Scheduler started
ERROR:[12/07/2021 22:03:08] No error handlers are registered, logging exception.
Traceback (most recent call last):
  File "C:\Python39\lib\site-packages\python_telegram_bot-13.4.1-py3.9.egg\telegram\ext\dispatcher.py", line 442, in process_update
    handler.handle_update(update, self, check, context)
  File "C:\Python39\lib\site-packages\python_telegram_bot-13.4.1-py3.9.egg\telegram\ext\conversationhandler.py", line 549, in handle_update
    new_state = handler.handle_update(update, dispatcher, check_result, context)
  File "C:\Python39\lib\site-packages\python_telegram_bot-13.4.1-py3.9.egg\telegram\ext\handler.py", line 160, in handle_update
    return self.callback(update, context)
  File "c:\Users\juanp\OneDrive\Escritorio\Repositorio\ChatWars\WaTavBot.py", line 1422, in buy
    Newcompra(622952731,weapon)
  File "c:\Users\juanp\OneDrive\Escritorio\Repositorio\ChatWars\WaTavBot.py", line 1454, in Newcompra
    "ataque": TiendaDB[items]["ataque"],
KeyError: 'ataque'
INFO:[12/07/2021 22:04:27] Received signal 2 (SIGINT), stopping...
INFO:[12/07/2021 22:04:27] Scheduler has been shut down
WARNING:[12/07/2021 22:04:27] Exiting immediately!
INFO:[12/07/2021 22:04:38] Scheduler started
ERROR:[12/07/2021 22:04:59] No error handlers are registered, logging exception.
Traceback (most recent call last):
  File "C:\Python39\lib\site-packages\python_telegram_bot-13.4.1-py3.9.egg\telegram\ext\dispatcher.py", line 442, in process_update
    handler.handle_update(update, self, check, context)
  File "C:\Python39\lib\site-packages\python_telegram_bot-13.4.1-py3.9.egg\telegram\ext\conversationhandler.py", line 549, in handle_update
    new_state = handler.handle_update(update, dispatcher, check_result, context)
  File "C:\Python39\lib\site-packages\python_telegram_bot-13.4.1-py3.9.egg\telegram\ext\handler.py", line 160, in handle_update
    return self.callback(update, context)
  File "c:\Users\juanp\OneDrive\Escritorio\Repositorio\ChatWars\WaTavBot.py", line 1136, in me
    text=+"\n\nüéΩEuipamiento: "
TypeError: bad operand type for unary +: 'str'
ERROR:[12/07/2021 22:05:04] No error handlers are registered, logging exception.
Traceback (most recent call last):
  File "C:\Python39\lib\site-packages\python_telegram_bot-13.4.1-py3.9.egg\telegram\ext\dispatcher.py", line 442, in process_update
    handler.handle_update(update, self, check, context)
  File "C:\Python39\lib\site-packages\python_telegram_bot-13.4.1-py3.9.egg\telegram\ext\conversationhandler.py", line 549, in handle_update
    new_state = handler.handle_update(update, dispatcher, check_result, context)
  File "C:\Python39\lib\site-packages\python_telegram_bot-13.4.1-py3.9.egg\telegram\ext\handler.py", line 160, in handle_update
    return self.callback(update, context)
  File "c:\Users\juanp\OneDrive\Escritorio\Repositorio\ChatWars\WaTavBot.py", line 1136, in me
    text=+"\n\nüéΩEuipamiento: "
TypeError: bad operand type for unary +: 'str'
ERROR:[12/07/2021 22:05:05] No error handlers are registered, logging exception.
Traceback (most recent call last):
  File "C:\Python39\lib\site-packages\python_telegram_bot-13.4.1-py3.9.egg\telegram\ext\dispatcher.py", line 442, in process_update
    handler.handle_update(update, self, check, context)
  File "C:\Python39\lib\site-packages\python_telegram_bot-13.4.1-py3.9.egg\telegram\ext\conversationhandler.py", line 549, in handle_update
    new_state = handler.handle_update(update, dispatcher, check_result, context)
  File "C:\Python39\lib\site-packages\python_telegram_bot-13.4.1-py3.9.egg\telegram\ext\handler.py", line 160, in handle_update
    return self.callback(update, context)
  File "c:\Users\juanp\OneDrive\Escritorio\Repositorio\ChatWars\WaTavBot.py", line 1136, in me
    text=+"\n\nüéΩEuipamiento: "
TypeError: bad operand type for unary +: 'str'
INFO:[12/07/2021 22:06:44] Received signal 2 (SIGINT), stopping...
INFO:[12/07/2021 22:06:44] Scheduler has been shut down
WARNING:[12/07/2021 22:06:44] Exiting immediately!
INFO:[12/07/2021 22:06:48] Scheduler started
INFO:[12/07/2021 22:07:58] Received signal 2 (SIGINT), stopping...
INFO:[12/07/2021 22:07:58] Scheduler has been shut down
WARNING:[12/07/2021 22:08:03] Exiting immediately!
INFO:[12/07/2021 22:08:07] Scheduler started
INFO:[12/07/2021 22:08:49] Received signal 2 (SIGINT), stopping...
INFO:[12/07/2021 22:08:49] Scheduler has been shut down
WARNING:[12/07/2021 22:08:49] Exiting immediately!
INFO:[12/07/2021 22:08:53] Scheduler started
INFO:[12/07/2021 22:09:13] Received signal 2 (SIGINT), stopping...
INFO:[12/07/2021 22:09:13] Scheduler has been shut down
WARNING:[12/07/2021 22:09:13] Exiting immediately!
INFO:[12/07/2021 22:09:17] Scheduler started
INFO:[12/07/2021 22:09:45] Received signal 2 (SIGINT), stopping...
INFO:[12/07/2021 22:09:45] Scheduler has been shut down
WARNING:[12/07/2021 22:09:45] Exiting immediately!
INFO:[12/07/2021 22:09:49] Scheduler started
INFO:[12/07/2021 22:10:03] Received signal 2 (SIGINT), stopping...
INFO:[12/07/2021 22:10:03] Scheduler has been shut down
WARNING:[12/07/2021 22:10:04] Exiting immediately!
INFO:[12/07/2021 22:10:24] Scheduler started
INFO:[12/07/2021 22:13:22] Scheduler started
INFO:[12/07/2021 22:14:58] Scheduler started
INFO:[12/07/2021 22:16:41] Scheduler started
ERROR:[12/07/2021 22:16:43] No error handlers are registered, logging exception.
Traceback (most recent call last):
  File "C:\Python39\lib\site-packages\python_telegram_bot-13.4.1-py3.9.egg\telegram\ext\dispatcher.py", line 442, in process_update
    handler.handle_update(update, self, check, context)
  File "C:\Python39\lib\site-packages\python_telegram_bot-13.4.1-py3.9.egg\telegram\ext\conversationhandler.py", line 549, in handle_update
    new_state = handler.handle_update(update, dispatcher, check_result, context)
  File "C:\Python39\lib\site-packages\python_telegram_bot-13.4.1-py3.9.egg\telegram\ext\handler.py", line 160, in handle_update
    return self.callback(update, context)
  File "c:\Users\juanp\OneDrive\Escritorio\Repositorio\ChatWars\WaTavBot.py", line 1422, in buy
    Newcompra(user=user.id,items=weapon)
  File "c:\Users\juanp\OneDrive\Escritorio\Repositorio\ChatWars\WaTavBot.py", line 1454, in Newcompra
    "ataque": TiendaDB[items]["ataque"],
KeyError: 'ataque'
INFO:[12/07/2021 22:17:11] Received signal 2 (SIGINT), stopping...
INFO:[12/07/2021 22:17:11] Scheduler has been shut down
WARNING:[12/07/2021 22:17:11] Exiting immediately!
INFO:[12/07/2021 22:17:15] Scheduler started
ERROR:[12/07/2021 22:17:21] No error handlers are registered, logging exception.
Traceback (most recent call last):
  File "C:\Python39\lib\site-packages\python_telegram_bot-13.4.1-py3.9.egg\telegram\ext\dispatcher.py", line 442, in process_update
    handler.handle_update(update, self, check, context)
  File "C:\Python39\lib\site-packages\python_telegram_bot-13.4.1-py3.9.egg\telegram\ext\conversationhandler.py", line 549, in handle_update
    new_state = handler.handle_update(update, dispatcher, check_result, context)
  File "C:\Python39\lib\site-packages\python_telegram_bot-13.4.1-py3.9.egg\telegram\ext\handler.py", line 160, in handle_update
    return self.callback(update, context)
  File "c:\Users\juanp\OneDrive\Escritorio\Repositorio\ChatWars\WaTavBot.py", line 1422, in buy
    Newcompra(user=user.id,items=weapon)
  File "c:\Users\juanp\OneDrive\Escritorio\Repositorio\ChatWars\WaTavBot.py", line 1484, in Newcompra
    Fire.put("/players",user.id,"/bolso_arm",items,info)
AttributeError: 'int' object has no attribute 'id'
INFO:[12/07/2021 22:18:02] Received signal 2 (SIGINT), stopping...
INFO:[12/07/2021 22:18:02] Scheduler has been shut down
WARNING:[12/07/2021 22:18:02] Exiting immediately!
INFO:[12/07/2021 22:18:06] Scheduler started
ERROR:[12/07/2021 22:18:08] No error handlers are registered, logging exception.
Traceback (most recent call last):
  File "C:\Python39\lib\site-packages\python_telegram_bot-13.4.1-py3.9.egg\telegram\ext\dispatcher.py", line 442, in process_update
    handler.handle_update(update, self, check, context)
  File "C:\Python39\lib\site-packages\python_telegram_bot-13.4.1-py3.9.egg\telegram\ext\conversationhandler.py", line 549, in handle_update
    new_state = handler.handle_update(update, dispatcher, check_result, context)
  File "C:\Python39\lib\site-packages\python_telegram_bot-13.4.1-py3.9.egg\telegram\ext\handler.py", line 160, in handle_update
    return self.callback(update, context)
  File "c:\Users\juanp\OneDrive\Escritorio\Repositorio\ChatWars\WaTavBot.py", line 1422, in buy
    Newcompra(user=user.id,items=weapon)
  File "c:\Users\juanp\OneDrive\Escritorio\Repositorio\ChatWars\WaTavBot.py", line 1484, in Newcompra
    Fire.put("/players",user.id,"/bolso_arm",items,info)
AttributeError: 'int' object has no attribute 'id'
INFO:[12/07/2021 22:19:08] Received signal 2 (SIGINT), stopping...
INFO:[12/07/2021 22:19:08] Scheduler has been shut down
WARNING:[12/07/2021 22:19:10] Exiting immediately!
INFO:[12/07/2021 22:19:15] Scheduler started
ERROR:[12/07/2021 22:19:18] No error handlers are registered, logging exception.
Traceback (most recent call last):
  File "C:\Python39\lib\site-packages\python_telegram_bot-13.4.1-py3.9.egg\telegram\ext\dispatcher.py", line 442, in process_update
    handler.handle_update(update, self, check, context)
  File "C:\Python39\lib\site-packages\python_telegram_bot-13.4.1-py3.9.egg\telegram\ext\conversationhandler.py", line 549, in handle_update
    new_state = handler.handle_update(update, dispatcher, check_result, context)
  File "C:\Python39\lib\site-packages\python_telegram_bot-13.4.1-py3.9.egg\telegram\ext\handler.py", line 160, in handle_update
    return self.callback(update, context)
  File "c:\Users\juanp\OneDrive\Escritorio\Repositorio\ChatWars\WaTavBot.py", line 1422, in buy
    Newcompra(user=user.id,items=weapon)
  File "c:\Users\juanp\OneDrive\Escritorio\Repositorio\ChatWars\WaTavBot.py", line 1484, in Newcompra
    Fire.put("/players",user.id,"/bolso_arm/",items,info)
AttributeError: 'int' object has no attribute 'id'
INFO:[12/07/2021 22:20:26] Received signal 2 (SIGINT), stopping...
INFO:[12/07/2021 22:20:26] Scheduler has been shut down
WARNING:[12/07/2021 22:20:26] Exiting immediately!
INFO:[12/07/2021 22:20:30] Scheduler started
ERROR:[12/07/2021 22:20:40] No error handlers are registered, logging exception.
Traceback (most recent call last):
  File "C:\Python39\lib\site-packages\python_telegram_bot-13.4.1-py3.9.egg\telegram\ext\dispatcher.py", line 442, in process_update
    handler.handle_update(update, self, check, context)
  File "C:\Python39\lib\site-packages\python_telegram_bot-13.4.1-py3.9.egg\telegram\ext\conversationhandler.py", line 549, in handle_update
    new_state = handler.handle_update(update, dispatcher, check_result, context)
  File "C:\Python39\lib\site-packages\python_telegram_bot-13.4.1-py3.9.egg\telegram\ext\handler.py", line 160, in handle_update
    return self.callback(update, context)
  File "c:\Users\juanp\OneDrive\Escritorio\Repositorio\ChatWars\WaTavBot.py", line 1422, in buy
    Newcompra(user=user.id,items=weapon)
  File "c:\Users\juanp\OneDrive\Escritorio\Repositorio\ChatWars\WaTavBot.py", line 1484, in Newcompra
    Fire.put("/players",str(user.id),"/bolso_arm/",str(items),info)
AttributeError: 'int' object has no attribute 'id'
INFO:[12/07/2021 22:21:23] Received signal 2 (SIGINT), stopping...
INFO:[12/07/2021 22:21:23] Scheduler has been shut down
WARNING:[12/07/2021 22:21:23] Exiting immediately!
INFO:[12/07/2021 22:21:31] Scheduler started
ERROR:[12/07/2021 22:22:15] No error handlers are registered, logging exception.
Traceback (most recent call last):
  File "C:\Python39\lib\site-packages\python_telegram_bot-13.4.1-py3.9.egg\telegram\ext\dispatcher.py", line 442, in process_update
    handler.handle_update(update, self, check, context)
  File "C:\Python39\lib\site-packages\python_telegram_bot-13.4.1-py3.9.egg\telegram\ext\conversationhandler.py", line 549, in handle_update
    new_state = handler.handle_update(update, dispatcher, check_result, context)
  File "C:\Python39\lib\site-packages\python_telegram_bot-13.4.1-py3.9.egg\telegram\ext\handler.py", line 160, in handle_update
    return self.callback(update, context)
  File "c:\Users\juanp\OneDrive\Escritorio\Repositorio\ChatWars\WaTavBot.py", line 1422, in buy
    Newcompra(user=user.id,items=weapon)
  File "c:\Users\juanp\OneDrive\Escritorio\Repositorio\ChatWars\WaTavBot.py", line 1484, in Newcompra
    Fire.put("/players",str(user.id),"/bolso_arm/",str(items),info)
AttributeError: 'int' object has no attribute 'id'
INFO:[12/07/2021 22:23:32] Scheduler started
ERROR:[12/07/2021 22:23:48] No error handlers are registered, logging exception.
Traceback (most recent call last):
  File "C:\Python39\lib\site-packages\python_telegram_bot-13.4.1-py3.9.egg\telegram\ext\dispatcher.py", line 442, in process_update
    handler.handle_update(update, self, check, context)
  File "C:\Python39\lib\site-packages\python_telegram_bot-13.4.1-py3.9.egg\telegram\ext\conversationhandler.py", line 549, in handle_update
    new_state = handler.handle_update(update, dispatcher, check_result, context)
  File "C:\Python39\lib\site-packages\python_telegram_bot-13.4.1-py3.9.egg\telegram\ext\handler.py", line 160, in handle_update
    return self.callback(update, context)
  File "c:\Users\juanp\OneDrive\Escritorio\Repositorio\ChatWars\WaTavBot.py", line 1422, in buy
    Newcompra(user=user.id,items=weapon)
  File "c:\Users\juanp\OneDrive\Escritorio\Repositorio\ChatWars\WaTavBot.py", line 1484, in Newcompra
    Fire.put("/players",user,"/bolso_arm/",items,info)
  File "C:\Python39\lib\site-packages\firebase\decorators.py", line 20, in wrapped
    return f(*args, **kwargs)
TypeError: put() got multiple values for argument 'connection'
INFO:[12/07/2021 22:24:06] Scheduler started
ERROR:[12/07/2021 22:24:08] No error handlers are registered, logging exception.
Traceback (most recent call last):
  File "C:\Python39\lib\site-packages\python_telegram_bot-13.4.1-py3.9.egg\telegram\ext\dispatcher.py", line 442, in process_update
    handler.handle_update(update, self, check, context)
  File "C:\Python39\lib\site-packages\python_telegram_bot-13.4.1-py3.9.egg\telegram\ext\conversationhandler.py", line 549, in handle_update
    new_state = handler.handle_update(update, dispatcher, check_result, context)
  File "C:\Python39\lib\site-packages\python_telegram_bot-13.4.1-py3.9.egg\telegram\ext\handler.py", line 160, in handle_update
    return self.callback(update, context)
  File "c:\Users\juanp\OneDrive\Escritorio\Repositorio\ChatWars\WaTavBot.py", line 1422, in buy
    Newcompra(user=user.id,items=weapon)
  File "c:\Users\juanp\OneDrive\Escritorio\Repositorio\ChatWars\WaTavBot.py", line 1484, in Newcompra
    Fire.put("/players",user,"/bolso_arm/",items,info)
  File "C:\Python39\lib\site-packages\firebase\decorators.py", line 20, in wrapped
    return f(*args, **kwargs)
TypeError: put() got multiple values for argument 'connection'
INFO:[12/07/2021 22:25:09] Received signal 2 (SIGINT), stopping...
INFO:[12/07/2021 22:25:09] Scheduler has been shut down
WARNING:[12/07/2021 22:25:10] Exiting immediately!
INFO:[12/07/2021 22:25:16] Scheduler started
ERROR:[12/07/2021 22:25:21] No error handlers are registered, logging exception.
Traceback (most recent call last):
  File "C:\Python39\lib\site-packages\python_telegram_bot-13.4.1-py3.9.egg\telegram\ext\dispatcher.py", line 442, in process_update
    handler.handle_update(update, self, check, context)
  File "C:\Python39\lib\site-packages\python_telegram_bot-13.4.1-py3.9.egg\telegram\ext\conversationhandler.py", line 549, in handle_update
    new_state = handler.handle_update(update, dispatcher, check_result, context)
  File "C:\Python39\lib\site-packages\python_telegram_bot-13.4.1-py3.9.egg\telegram\ext\handler.py", line 160, in handle_update
    return self.callback(update, context)
  File "c:\Users\juanp\OneDrive\Escritorio\Repositorio\ChatWars\WaTavBot.py", line 1422, in buy
    Newcompra(user=user.id,items=weapon)
  File "c:\Users\juanp\OneDrive\Escritorio\Repositorio\ChatWars\WaTavBot.py", line 1484, in Newcompra
    Fire.post("/players",user,"/bolso_arm/",items,info)
  File "C:\Python39\lib\site-packages\firebase\decorators.py", line 20, in wrapped
    return f(*args, **kwargs)
TypeError: post() got multiple values for argument 'connection'
INFO:[12/07/2021 22:26:10] Received signal 2 (SIGINT), stopping...
INFO:[12/07/2021 22:26:10] Scheduler has been shut down
WARNING:[12/07/2021 22:26:11] Exiting immediately!
INFO:[12/07/2021 22:26:14] Scheduler started
ERROR:[12/07/2021 22:26:18] No error handlers are registered, logging exception.
Traceback (most recent call last):
  File "C:\Python39\lib\site-packages\python_telegram_bot-13.4.1-py3.9.egg\telegram\ext\dispatcher.py", line 442, in process_update
    handler.handle_update(update, self, check, context)
  File "C:\Python39\lib\site-packages\python_telegram_bot-13.4.1-py3.9.egg\telegram\ext\conversationhandler.py", line 549, in handle_update
    new_state = handler.handle_update(update, dispatcher, check_result, context)
  File "C:\Python39\lib\site-packages\python_telegram_bot-13.4.1-py3.9.egg\telegram\ext\handler.py", line 160, in handle_update
    return self.callback(update, context)
  File "c:\Users\juanp\OneDrive\Escritorio\Repositorio\ChatWars\WaTavBot.py", line 1422, in buy
    Newcompra(user=user.id,items=weapon)
  File "c:\Users\juanp\OneDrive\Escritorio\Repositorio\ChatWars\WaTavBot.py", line 1484, in Newcompra
    Fire.put("/players",user,"bolso_arm",items,info)
  File "C:\Python39\lib\site-packages\firebase\decorators.py", line 20, in wrapped
    return f(*args, **kwargs)
TypeError: put() got multiple values for argument 'connection'
INFO:[12/07/2021 22:27:59] Received signal 2 (SIGINT), stopping...
INFO:[12/07/2021 22:27:59] Scheduler has been shut down
WARNING:[12/07/2021 22:27:59] Exiting immediately!
INFO:[12/07/2021 22:28:04] Scheduler started
ERROR:[12/07/2021 22:28:07] No error handlers are registered, logging exception.
Traceback (most recent call last):
  File "C:\Python39\lib\site-packages\python_telegram_bot-13.4.1-py3.9.egg\telegram\ext\dispatcher.py", line 442, in process_update
    handler.handle_update(update, self, check, context)
  File "C:\Python39\lib\site-packages\python_telegram_bot-13.4.1-py3.9.egg\telegram\ext\conversationhandler.py", line 549, in handle_update
    new_state = handler.handle_update(update, dispatcher, check_result, context)
  File "C:\Python39\lib\site-packages\python_telegram_bot-13.4.1-py3.9.egg\telegram\ext\handler.py", line 160, in handle_update
    return self.callback(update, context)
  File "c:\Users\juanp\OneDrive\Escritorio\Repositorio\ChatWars\WaTavBot.py", line 1422, in buy
    Newcompra(user=user.id,items=weapon)
  File "c:\Users\juanp\OneDrive\Escritorio\Repositorio\ChatWars\WaTavBot.py", line 1484, in Newcompra
    Fire.put("/players",user,"bolso_arm",items=info)
  File "C:\Python39\lib\site-packages\firebase\decorators.py", line 20, in wrapped
    return f(*args, **kwargs)
TypeError: put() got an unexpected keyword argument 'items'
INFO:[12/07/2021 22:28:39] Received signal 2 (SIGINT), stopping...
INFO:[12/07/2021 22:28:39] Scheduler has been shut down
WARNING:[12/07/2021 22:28:40] Exiting immediately!
INFO:[12/07/2021 22:28:43] Scheduler started
ERROR:[12/07/2021 22:28:45] No error handlers are registered, logging exception.
Traceback (most recent call last):
  File "C:\Python39\lib\site-packages\python_telegram_bot-13.4.1-py3.9.egg\telegram\ext\dispatcher.py", line 442, in process_update
    handler.handle_update(update, self, check, context)
  File "C:\Python39\lib\site-packages\python_telegram_bot-13.4.1-py3.9.egg\telegram\ext\conversationhandler.py", line 549, in handle_update
    new_state = handler.handle_update(update, dispatcher, check_result, context)
  File "C:\Python39\lib\site-packages\python_telegram_bot-13.4.1-py3.9.egg\telegram\ext\handler.py", line 160, in handle_update
    return self.callback(update, context)
  File "c:\Users\juanp\OneDrive\Escritorio\Repositorio\ChatWars\WaTavBot.py", line 1422, in buy
    Newcompra(user=user.id,items=weapon)
  File "c:\Users\juanp\OneDrive\Escritorio\Repositorio\ChatWars\WaTavBot.py", line 1484, in Newcompra
    Fire.put("/players",user,"/bolso_arm/",items+"/",info)
  File "C:\Python39\lib\site-packages\firebase\decorators.py", line 20, in wrapped
    return f(*args, **kwargs)
TypeError: put() got multiple values for argument 'connection'
INFO:[12/07/2021 22:29:04] Received signal 2 (SIGINT), stopping...
INFO:[12/07/2021 22:29:04] Scheduler has been shut down
WARNING:[12/07/2021 22:29:04] Exiting immediately!
INFO:[12/07/2021 22:29:08] Scheduler started
ERROR:[12/07/2021 22:29:10] No error handlers are registered, logging exception.
Traceback (most recent call last):
  File "C:\Python39\lib\site-packages\python_telegram_bot-13.4.1-py3.9.egg\telegram\ext\dispatcher.py", line 442, in process_update
    handler.handle_update(update, self, check, context)
  File "C:\Python39\lib\site-packages\python_telegram_bot-13.4.1-py3.9.egg\telegram\ext\conversationhandler.py", line 549, in handle_update
    new_state = handler.handle_update(update, dispatcher, check_result, context)
  File "C:\Python39\lib\site-packages\python_telegram_bot-13.4.1-py3.9.egg\telegram\ext\handler.py", line 160, in handle_update
    return self.callback(update, context)
  File "c:\Users\juanp\OneDrive\Escritorio\Repositorio\ChatWars\WaTavBot.py", line 1422, in buy
    Newcompra(user=user.id,items=weapon)
  File "c:\Users\juanp\OneDrive\Escritorio\Repositorio\ChatWars\WaTavBot.py", line 1484, in Newcompra
    Fire.put("/players",user,"/bolso_arm/",items,"/",info)
  File "C:\Python39\lib\site-packages\firebase\decorators.py", line 20, in wrapped
    return f(*args, **kwargs)
TypeError: put() got multiple values for argument 'connection'
INFO:[12/07/2021 22:51:32] Received signal 2 (SIGINT), stopping...
INFO:[12/07/2021 22:51:32] Scheduler has been shut down
WARNING:[12/07/2021 22:51:32] Exiting immediately!
INFO:[12/07/2021 22:51:36] Scheduler started
ERROR:[12/07/2021 22:51:46] No error handlers are registered, logging exception.
Traceback (most recent call last):
  File "C:\Python39\lib\site-packages\python_telegram_bot-13.4.1-py3.9.egg\telegram\ext\dispatcher.py", line 442, in process_update
    handler.handle_update(update, self, check, context)
  File "C:\Python39\lib\site-packages\python_telegram_bot-13.4.1-py3.9.egg\telegram\ext\conversationhandler.py", line 549, in handle_update
    new_state = handler.handle_update(update, dispatcher, check_result, context)
  File "C:\Python39\lib\site-packages\python_telegram_bot-13.4.1-py3.9.egg\telegram\ext\handler.py", line 160, in handle_update
    return self.callback(update, context)
  File "c:\Users\juanp\OneDrive\Escritorio\Repositorio\ChatWars\WaTavBot.py", line 1422, in buy
    Newcompra(user=user.id,items=weapon)
  File "c:\Users\juanp\OneDrive\Escritorio\Repositorio\ChatWars\WaTavBot.py", line 1454, in Newcompra
    Fire.put("/players/",user,"/bolso_arm/",items,info)
  File "C:\Python39\lib\site-packages\firebase\decorators.py", line 20, in wrapped
    return f(*args, **kwargs)
TypeError: put() got multiple values for argument 'connection'
INFO:[12/07/2021 22:58:28] Received signal 2 (SIGINT), stopping...
INFO:[12/07/2021 22:58:28] Scheduler has been shut down
WARNING:[12/07/2021 22:58:28] Exiting immediately!
INFO:[12/07/2021 22:58:32] Scheduler started
ERROR:[12/07/2021 22:58:39] No error handlers are registered, logging exception.
Traceback (most recent call last):
  File "C:\Python39\lib\site-packages\python_telegram_bot-13.4.1-py3.9.egg\telegram\ext\dispatcher.py", line 442, in process_update
    handler.handle_update(update, self, check, context)
  File "C:\Python39\lib\site-packages\python_telegram_bot-13.4.1-py3.9.egg\telegram\ext\conversationhandler.py", line 549, in handle_update
    new_state = handler.handle_update(update, dispatcher, check_result, context)
  File "C:\Python39\lib\site-packages\python_telegram_bot-13.4.1-py3.9.egg\telegram\ext\handler.py", line 160, in handle_update
    return self.callback(update, context)
  File "c:\Users\juanp\OneDrive\Escritorio\Repositorio\ChatWars\WaTavBot.py", line 1422, in buy
    Newcompra(user=user.id,items=weapon)
  File "c:\Users\juanp\OneDrive\Escritorio\Repositorio\ChatWars\WaTavBot.py", line 1484, in Newcompra
    Fire.put("/players",user,"/bolso_arm",items=info)
  File "C:\Python39\lib\site-packages\firebase\decorators.py", line 20, in wrapped
    return f(*args, **kwargs)
TypeError: put() got an unexpected keyword argument 'items'
INFO:[12/07/2021 22:59:22] Received signal 2 (SIGINT), stopping...
INFO:[12/07/2021 22:59:22] Scheduler has been shut down
WARNING:[12/07/2021 22:59:22] Exiting immediately!
INFO:[12/07/2021 22:59:26] Scheduler started
ERROR:[12/07/2021 22:59:28] No error handlers are registered, logging exception.
Traceback (most recent call last):
  File "C:\Python39\lib\site-packages\python_telegram_bot-13.4.1-py3.9.egg\telegram\ext\dispatcher.py", line 442, in process_update
    handler.handle_update(update, self, check, context)
  File "C:\Python39\lib\site-packages\python_telegram_bot-13.4.1-py3.9.egg\telegram\ext\conversationhandler.py", line 549, in handle_update
    new_state = handler.handle_update(update, dispatcher, check_result, context)
  File "C:\Python39\lib\site-packages\python_telegram_bot-13.4.1-py3.9.egg\telegram\ext\handler.py", line 160, in handle_update
    return self.callback(update, context)
  File "c:\Users\juanp\OneDrive\Escritorio\Repositorio\ChatWars\WaTavBot.py", line 1422, in buy
    Newcompra(user=user.id,items=weapon)
  File "c:\Users\juanp\OneDrive\Escritorio\Repositorio\ChatWars\WaTavBot.py", line 1484, in Newcompra
    Fire.put("/players",user,"/bolso_arm",items,"/",info)
  File "C:\Python39\lib\site-packages\firebase\decorators.py", line 20, in wrapped
    return f(*args, **kwargs)
TypeError: put() got multiple values for argument 'connection'
ERROR:[12/07/2021 23:12:16] No error handlers are registered, logging exception.
Traceback (most recent call last):
  File "C:\Python39\lib\site-packages\python_telegram_bot-13.4.1-py3.9.egg\telegram\ext\dispatcher.py", line 442, in process_update
    handler.handle_update(update, self, check, context)
  File "C:\Python39\lib\site-packages\python_telegram_bot-13.4.1-py3.9.egg\telegram\ext\conversationhandler.py", line 549, in handle_update
    new_state = handler.handle_update(update, dispatcher, check_result, context)
  File "C:\Python39\lib\site-packages\python_telegram_bot-13.4.1-py3.9.egg\telegram\ext\handler.py", line 160, in handle_update
    return self.callback(update, context)
  File "c:\Users\juanp\OneDrive\Escritorio\Repositorio\ChatWars\WaTavBot.py", line 1136, in me
    text=+"\n\nüéΩEuipamiento: "
TypeError: bad operand type for unary +: 'str'
INFO:[12/07/2021 23:13:00] Received signal 2 (SIGINT), stopping...
INFO:[12/07/2021 23:13:00] Scheduler has been shut down
WARNING:[12/07/2021 23:13:00] Exiting immediately!
INFO:[12/07/2021 23:13:05] Scheduler started
ERROR:[12/07/2021 23:13:09] No error handlers are registered, logging exception.
Traceback (most recent call last):
  File "C:\Python39\lib\site-packages\python_telegram_bot-13.4.1-py3.9.egg\telegram\ext\dispatcher.py", line 442, in process_update
    handler.handle_update(update, self, check, context)
  File "C:\Python39\lib\site-packages\python_telegram_bot-13.4.1-py3.9.egg\telegram\ext\conversationhandler.py", line 549, in handle_update
    new_state = handler.handle_update(update, dispatcher, check_result, context)
  File "C:\Python39\lib\site-packages\python_telegram_bot-13.4.1-py3.9.egg\telegram\ext\handler.py", line 160, in handle_update
    return self.callback(update, context)
  File "c:\Users\juanp\OneDrive\Escritorio\Repositorio\ChatWars\WaTavBot.py", line 1141, in me
    +"\n\nEstado:\n{estado}".format(estado=player["estado"])
TypeError: bad operand type for unary +: 'str'
ERROR:[12/07/2021 23:13:10] No error handlers are registered, logging exception.
Traceback (most recent call last):
  File "C:\Python39\lib\site-packages\python_telegram_bot-13.4.1-py3.9.egg\telegram\ext\dispatcher.py", line 442, in process_update
    handler.handle_update(update, self, check, context)
  File "C:\Python39\lib\site-packages\python_telegram_bot-13.4.1-py3.9.egg\telegram\ext\conversationhandler.py", line 549, in handle_update
    new_state = handler.handle_update(update, dispatcher, check_result, context)
  File "C:\Python39\lib\site-packages\python_telegram_bot-13.4.1-py3.9.egg\telegram\ext\handler.py", line 160, in handle_update
    return self.callback(update, context)
  File "c:\Users\juanp\OneDrive\Escritorio\Repositorio\ChatWars\WaTavBot.py", line 1141, in me
    +"\n\nEstado:\n{estado}".format(estado=player["estado"])
TypeError: bad operand type for unary +: 'str'
ERROR:[12/07/2021 23:13:12] No error handlers are registered, logging exception.
Traceback (most recent call last):
  File "C:\Python39\lib\site-packages\python_telegram_bot-13.4.1-py3.9.egg\telegram\ext\dispatcher.py", line 442, in process_update
    handler.handle_update(update, self, check, context)
  File "C:\Python39\lib\site-packages\python_telegram_bot-13.4.1-py3.9.egg\telegram\ext\conversationhandler.py", line 549, in handle_update
    new_state = handler.handle_update(update, dispatcher, check_result, context)
  File "C:\Python39\lib\site-packages\python_telegram_bot-13.4.1-py3.9.egg\telegram\ext\handler.py", line 160, in handle_update
    return self.callback(update, context)
  File "c:\Users\juanp\OneDrive\Escritorio\Repositorio\ChatWars\WaTavBot.py", line 1141, in me
    +"\n\nEstado:\n{estado}".format(estado=player["estado"])
TypeError: bad operand type for unary +: 'str'
INFO:[12/07/2021 23:15:32] Received signal 2 (SIGINT), stopping...
INFO:[12/07/2021 23:15:32] Scheduler has been shut down
WARNING:[12/07/2021 23:15:32] Exiting immediately!
INFO:[12/07/2021 23:15:36] Scheduler started
ERROR:[12/07/2021 23:16:08] No error handlers are registered, logging exception.
Traceback (most recent call last):
  File "C:\Python39\lib\site-packages\python_telegram_bot-13.4.1-py3.9.egg\telegram\ext\dispatcher.py", line 442, in process_update
    handler.handle_update(update, self, check, context)
  File "C:\Python39\lib\site-packages\python_telegram_bot-13.4.1-py3.9.egg\telegram\ext\conversationhandler.py", line 549, in handle_update
    new_state = handler.handle_update(update, dispatcher, check_result, context)
  File "C:\Python39\lib\site-packages\python_telegram_bot-13.4.1-py3.9.egg\telegram\ext\handler.py", line 160, in handle_update
    return self.callback(update, context)
  File "c:\Users\juanp\OneDrive\Escritorio\Repositorio\ChatWars\WaTavBot.py", line 1422, in buy
    Newcompra(user=user.id,items=weapon)
  File "c:\Users\juanp\OneDrive\Escritorio\Repositorio\ChatWars\WaTavBot.py", line 1485, in Newcompra
    Fire.put("/players",user,"/bolso_arm",items,"/",info)
  File "C:\Python39\lib\site-packages\firebase\decorators.py", line 20, in wrapped
    return f(*args, **kwargs)
TypeError: put() got multiple values for argument 'connection'
INFO:[12/07/2021 23:16:54] Received signal 2 (SIGINT), stopping...
INFO:[12/07/2021 23:16:54] Scheduler has been shut down
WARNING:[12/07/2021 23:16:55] Exiting immediately!
INFO:[12/07/2021 23:16:58] Scheduler started
WARNING:[12/07/2021 23:17:01] Actualizar: 
‚îÇ
‚îúupdate_id: 994731076
‚îîmessage:
‚†Ä‚îúmessage_id: 4702
‚†Ä‚îúdate: 1626146218
‚†Ä‚îúchat:
‚îÇ‚îÇ‚îúid: 622952731
‚îÇ‚îÇ‚îútype: private
‚îÇ‚îÇ‚îúusername: JuanShotLC
‚îÇ‚îÇ‚îúfirst_name: üëë JuanShotLC üëë
‚îÇ‚îÇ‚îîlast_name: ‚öíÔ∏è ¬≤‚Å∑
‚†Ä‚îútext: /buy_03
‚†Ä‚îúentities:
‚îÇ‚îÇ‚îî0:
‚îÇ‚îÇ‚†Ä‚îútype: bot_command
‚îÇ‚îÇ‚†Ä‚îúoffset: 0
‚îÇ‚îÇ‚†Ä‚îîlength: 7
‚†Ä‚îúcaption_entities:
‚†Ä‚îúphoto:
‚†Ä‚îúnew_chat_members:
‚†Ä‚îúnew_chat_photo:
‚†Ä‚îúdelete_chat_photo: False
‚†Ä‚îúgroup_chat_created: False
‚†Ä‚îúsupergroup_chat_created: False
‚†Ä‚îúchannel_chat_created: False
‚†Ä‚îîfrom:
‚îÇ‚†Ä‚îúid: 622952731
‚îÇ‚†Ä‚îúfirst_name: üëë JuanShotLC üëë
‚îÇ‚†Ä‚îúis_bot: False
‚îÇ‚†Ä‚îúlast_name: ‚öíÔ∏è ¬≤‚Å∑
‚îÇ‚†Ä‚îúusername: JuanShotLC
‚îÇ‚†Ä‚îîlanguage_code: es 
...Error causado : 

&lt;class &#x27;TypeError&#x27;&gt;:put() got multiple values for argument &#x27;connection&#x27; en WaTavBot.py en la linea 1422

Notas: put() got multiple values for argument &#x27;connection&#x27;
INFO:[12/07/2021 23:17:15] Received signal 2 (SIGINT), stopping...
INFO:[12/07/2021 23:17:15] Scheduler has been shut down
WARNING:[12/07/2021 23:17:15] Exiting immediately!
